2020-10-03 09:16:40,473 INFO: Futbolero startup [in /home/guido/Dropbox/cs50x/final_project/app/__init__.py:42]
2020-10-03 10:29:07,707 INFO: Futbolero startup [in /home/guido/Dropbox/cs50x/final_project/app/__init__.py:42]
2020-10-03 10:35:58,585 INFO: Futbolero startup [in /home/guido/Dropbox/cs50x/final_project/app/__init__.py:42]
2020-10-03 11:14:23,496 INFO: Futbolero startup [in /home/guido/Dropbox/cs50x/final_project/app/__init__.py:42]
2020-10-03 11:16:18,932 INFO: Futbolero startup [in /home/guido/Dropbox/cs50x/final_project/app/__init__.py:42]
2020-10-03 11:16:28,718 ERROR: Exception on /login [GET] [in /home/guido/anaconda3/envs/local/lib/python3.8/site-packages/flask/app.py:1891]
Traceback (most recent call last):
  File "/home/guido/anaconda3/envs/local/lib/python3.8/site-packages/flask/app.py", line 2447, in wsgi_app
    response = self.full_dispatch_request()
  File "/home/guido/anaconda3/envs/local/lib/python3.8/site-packages/flask/app.py", line 1952, in full_dispatch_request
    rv = self.handle_user_exception(e)
  File "/home/guido/anaconda3/envs/local/lib/python3.8/site-packages/flask/app.py", line 1821, in handle_user_exception
    reraise(exc_type, exc_value, tb)
  File "/home/guido/anaconda3/envs/local/lib/python3.8/site-packages/flask/_compat.py", line 39, in reraise
    raise value
  File "/home/guido/anaconda3/envs/local/lib/python3.8/site-packages/flask/app.py", line 1950, in full_dispatch_request
    rv = self.dispatch_request()
  File "/home/guido/anaconda3/envs/local/lib/python3.8/site-packages/flask/app.py", line 1936, in dispatch_request
    return self.view_functions[rule.endpoint](**req.view_args)
  File "/home/guido/Dropbox/cs50x/final_project/app/routes.py", line 62, in login
    return render_template('login.html', title='Ingresar', form=form)
  File "/home/guido/anaconda3/envs/local/lib/python3.8/site-packages/flask/templating.py", line 137, in render_template
    return _render(
  File "/home/guido/anaconda3/envs/local/lib/python3.8/site-packages/flask/templating.py", line 120, in _render
    rv = template.render(context)
  File "/home/guido/anaconda3/envs/local/lib/python3.8/site-packages/jinja2/environment.py", line 1090, in render
    self.environment.handle_exception()
  File "/home/guido/anaconda3/envs/local/lib/python3.8/site-packages/jinja2/environment.py", line 832, in handle_exception
    reraise(*rewrite_traceback_stack(source=source))
  File "/home/guido/anaconda3/envs/local/lib/python3.8/site-packages/jinja2/_compat.py", line 28, in reraise
    raise value.with_traceback(tb)
  File "/home/guido/Dropbox/cs50x/final_project/app/templates/login.html", line 1, in top-level template code
    <!-- {% extends "base.html" %}
jinja2.exceptions.TemplateRuntimeError: extended multiple times
2020-10-03 11:20:23,683 INFO: Futbolero startup [in /home/guido/Dropbox/cs50x/final_project/app/__init__.py:42]
2020-10-03 11:20:54,965 ERROR: Exception on /user/guido [GET] [in /home/guido/anaconda3/envs/local/lib/python3.8/site-packages/flask/app.py:1891]
Traceback (most recent call last):
  File "/home/guido/anaconda3/envs/local/lib/python3.8/site-packages/flask/app.py", line 2447, in wsgi_app
    response = self.full_dispatch_request()
  File "/home/guido/anaconda3/envs/local/lib/python3.8/site-packages/flask/app.py", line 1952, in full_dispatch_request
    rv = self.handle_user_exception(e)
  File "/home/guido/anaconda3/envs/local/lib/python3.8/site-packages/flask/app.py", line 1821, in handle_user_exception
    reraise(exc_type, exc_value, tb)
  File "/home/guido/anaconda3/envs/local/lib/python3.8/site-packages/flask/_compat.py", line 39, in reraise
    raise value
  File "/home/guido/anaconda3/envs/local/lib/python3.8/site-packages/flask/app.py", line 1950, in full_dispatch_request
    rv = self.dispatch_request()
  File "/home/guido/anaconda3/envs/local/lib/python3.8/site-packages/flask/app.py", line 1936, in dispatch_request
    return self.view_functions[rule.endpoint](**req.view_args)
  File "/home/guido/anaconda3/envs/local/lib/python3.8/site-packages/flask_login/utils.py", line 272, in decorated_view
    return func(*args, **kwargs)
  File "/home/guido/Dropbox/cs50x/final_project/app/routes.py", line 102, in user
    if users[row].id == users_points[row][0]:
IndexError: list index out of range
2020-10-03 11:24:36,345 INFO: Futbolero startup [in /home/guido/Dropbox/cs50x/final_project/app/__init__.py:42]
2020-10-03 11:24:58,141 ERROR: Exception on /user/guido [GET] [in /home/guido/anaconda3/envs/local/lib/python3.8/site-packages/flask/app.py:1891]
Traceback (most recent call last):
  File "/home/guido/anaconda3/envs/local/lib/python3.8/site-packages/flask/app.py", line 2447, in wsgi_app
    response = self.full_dispatch_request()
  File "/home/guido/anaconda3/envs/local/lib/python3.8/site-packages/flask/app.py", line 1952, in full_dispatch_request
    rv = self.handle_user_exception(e)
  File "/home/guido/anaconda3/envs/local/lib/python3.8/site-packages/flask/app.py", line 1821, in handle_user_exception
    reraise(exc_type, exc_value, tb)
  File "/home/guido/anaconda3/envs/local/lib/python3.8/site-packages/flask/_compat.py", line 39, in reraise
    raise value
  File "/home/guido/anaconda3/envs/local/lib/python3.8/site-packages/flask/app.py", line 1950, in full_dispatch_request
    rv = self.dispatch_request()
  File "/home/guido/anaconda3/envs/local/lib/python3.8/site-packages/flask/app.py", line 1936, in dispatch_request
    return self.view_functions[rule.endpoint](**req.view_args)
  File "/home/guido/anaconda3/envs/local/lib/python3.8/site-packages/flask_login/utils.py", line 272, in decorated_view
    return func(*args, **kwargs)
  File "/home/guido/Dropbox/cs50x/final_project/app/routes.py", line 105, in user
    if users[row].id == users_points[row][0]:
IndexError: list index out of range
2020-10-03 11:31:00,329 INFO: Futbolero startup [in /home/guido/Dropbox/cs50x/final_project/app/__init__.py:42]
2020-10-03 11:32:11,264 ERROR: Exception on /user/guido [GET] [in /home/guido/anaconda3/envs/local/lib/python3.8/site-packages/flask/app.py:1891]
Traceback (most recent call last):
  File "/home/guido/anaconda3/envs/local/lib/python3.8/site-packages/flask/app.py", line 2447, in wsgi_app
    response = self.full_dispatch_request()
  File "/home/guido/anaconda3/envs/local/lib/python3.8/site-packages/flask/app.py", line 1952, in full_dispatch_request
    rv = self.handle_user_exception(e)
  File "/home/guido/anaconda3/envs/local/lib/python3.8/site-packages/flask/app.py", line 1821, in handle_user_exception
    reraise(exc_type, exc_value, tb)
  File "/home/guido/anaconda3/envs/local/lib/python3.8/site-packages/flask/_compat.py", line 39, in reraise
    raise value
  File "/home/guido/anaconda3/envs/local/lib/python3.8/site-packages/flask/app.py", line 1950, in full_dispatch_request
    rv = self.dispatch_request()
  File "/home/guido/anaconda3/envs/local/lib/python3.8/site-packages/flask/app.py", line 1936, in dispatch_request
    return self.view_functions[rule.endpoint](**req.view_args)
  File "/home/guido/anaconda3/envs/local/lib/python3.8/site-packages/flask_login/utils.py", line 272, in decorated_view
    return func(*args, **kwargs)
  File "/home/guido/Dropbox/cs50x/final_project/app/routes.py", line 105, in user
    if users[row].id == users_points[row][0].id:
AttributeError: 'int' object has no attribute 'id'
2020-10-03 11:33:33,717 INFO: Futbolero startup [in /home/guido/Dropbox/cs50x/final_project/app/__init__.py:42]
2020-10-03 11:33:52,975 ERROR: Exception on /user/guido [GET] [in /home/guido/anaconda3/envs/local/lib/python3.8/site-packages/flask/app.py:1891]
Traceback (most recent call last):
  File "/home/guido/anaconda3/envs/local/lib/python3.8/site-packages/flask/app.py", line 2447, in wsgi_app
    response = self.full_dispatch_request()
  File "/home/guido/anaconda3/envs/local/lib/python3.8/site-packages/flask/app.py", line 1952, in full_dispatch_request
    rv = self.handle_user_exception(e)
  File "/home/guido/anaconda3/envs/local/lib/python3.8/site-packages/flask/app.py", line 1821, in handle_user_exception
    reraise(exc_type, exc_value, tb)
  File "/home/guido/anaconda3/envs/local/lib/python3.8/site-packages/flask/_compat.py", line 39, in reraise
    raise value
  File "/home/guido/anaconda3/envs/local/lib/python3.8/site-packages/flask/app.py", line 1950, in full_dispatch_request
    rv = self.dispatch_request()
  File "/home/guido/anaconda3/envs/local/lib/python3.8/site-packages/flask/app.py", line 1936, in dispatch_request
    return self.view_functions[rule.endpoint](**req.view_args)
  File "/home/guido/anaconda3/envs/local/lib/python3.8/site-packages/flask_login/utils.py", line 272, in decorated_view
    return func(*args, **kwargs)
  File "/home/guido/Dropbox/cs50x/final_project/app/routes.py", line 105, in user
    if users[row].id == users_points[row][0]:
IndexError: list index out of range
2020-10-03 12:07:40,249 INFO: Futbolero startup [in /home/guido/Dropbox/cs50x/final_project/app/__init__.py:42]
2020-10-03 12:08:13,745 INFO: Futbolero startup [in /home/guido/Dropbox/cs50x/final_project/app/__init__.py:42]
2020-10-03 12:08:27,727 INFO: Futbolero startup [in /home/guido/Dropbox/cs50x/final_project/app/__init__.py:42]
2020-10-03 12:08:45,406 INFO: Futbolero startup [in /home/guido/Dropbox/cs50x/final_project/app/__init__.py:42]
2020-10-03 12:09:26,716 INFO: Futbolero startup [in /home/guido/Dropbox/cs50x/final_project/app/__init__.py:42]
2020-10-03 12:16:23,719 INFO: Futbolero startup [in /home/guido/Dropbox/cs50x/final_project/app/__init__.py:42]
2020-10-03 12:23:28,446 INFO: Futbolero startup [in /home/guido/Dropbox/cs50x/final_project/app/__init__.py:42]
2020-10-03 12:23:51,277 INFO: Futbolero startup [in /home/guido/Dropbox/cs50x/final_project/app/__init__.py:42]
2020-10-03 12:24:14,774 INFO: Futbolero startup [in /home/guido/Dropbox/cs50x/final_project/app/__init__.py:42]
