2020-09-24 15:51:07,987 ERROR: Exception on /bet [GET] [in /home/guido/anaconda3/envs/local/lib/python3.8/site-packages/flask/app.py:1891]
Traceback (most recent call last):
  File "/home/guido/anaconda3/envs/local/lib/python3.8/site-packages/flask/app.py", line 2447, in wsgi_app
    response = self.full_dispatch_request()
  File "/home/guido/anaconda3/envs/local/lib/python3.8/site-packages/flask/app.py", line 1952, in full_dispatch_request
    rv = self.handle_user_exception(e)
  File "/home/guido/anaconda3/envs/local/lib/python3.8/site-packages/flask/app.py", line 1821, in handle_user_exception
    reraise(exc_type, exc_value, tb)
  File "/home/guido/anaconda3/envs/local/lib/python3.8/site-packages/flask/_compat.py", line 39, in reraise
    raise value
  File "/home/guido/anaconda3/envs/local/lib/python3.8/site-packages/flask/app.py", line 1950, in full_dispatch_request
    rv = self.dispatch_request()
  File "/home/guido/anaconda3/envs/local/lib/python3.8/site-packages/flask/app.py", line 1936, in dispatch_request
    return self.view_functions[rule.endpoint](**req.view_args)
  File "/home/guido/anaconda3/envs/local/lib/python3.8/site-packages/flask_login/utils.py", line 272, in decorated_view
    return func(*args, **kwargs)
  File "/home/guido/Dropbox/cs50x/final_project/app/routes.py", line 175, in bet
    return render_template("bet.html", title='Home Page', table=next_round, form=form)
  File "/home/guido/anaconda3/envs/local/lib/python3.8/site-packages/flask/templating.py", line 138, in render_template
    ctx.app.jinja_env.get_or_select_template(template_name_or_list),
  File "/home/guido/anaconda3/envs/local/lib/python3.8/site-packages/jinja2/environment.py", line 930, in get_or_select_template
    return self.get_template(template_name_or_list, parent, globals)
  File "/home/guido/anaconda3/envs/local/lib/python3.8/site-packages/jinja2/environment.py", line 883, in get_template
    return self._load_template(name, self.make_globals(globals))
  File "/home/guido/anaconda3/envs/local/lib/python3.8/site-packages/jinja2/environment.py", line 857, in _load_template
    template = self.loader.load(self, name, globals)
  File "/home/guido/anaconda3/envs/local/lib/python3.8/site-packages/jinja2/loaders.py", line 127, in load
    code = environment.compile(source, name, filename)
  File "/home/guido/anaconda3/envs/local/lib/python3.8/site-packages/jinja2/environment.py", line 638, in compile
    self.handle_exception(source=source_hint)
  File "/home/guido/anaconda3/envs/local/lib/python3.8/site-packages/jinja2/environment.py", line 832, in handle_exception
    reraise(*rewrite_traceback_stack(source=source))
  File "/home/guido/anaconda3/envs/local/lib/python3.8/site-packages/jinja2/_compat.py", line 28, in reraise
    raise value.with_traceback(tb)
  File "/home/guido/Dropbox/cs50x/final_project/app/templates/bet.html", line 59, in template
    {% endblock %}
jinja2.exceptions.TemplateSyntaxError: Encountered unknown tag 'endblock'. You probably made a nesting mistake. Jinja is expecting this tag, but currently looking for 'endwith'. The innermost block that needs to be closed is 'with'.
2020-09-24 15:52:10,495 INFO: Futbolero startup [in /home/guido/Dropbox/cs50x/final_project/app/__init__.py:37]
2020-09-24 15:52:21,094 ERROR: Exception on /bet [GET] [in /home/guido/anaconda3/envs/local/lib/python3.8/site-packages/flask/app.py:1891]
Traceback (most recent call last):
  File "/home/guido/anaconda3/envs/local/lib/python3.8/site-packages/flask/app.py", line 2447, in wsgi_app
    response = self.full_dispatch_request()
  File "/home/guido/anaconda3/envs/local/lib/python3.8/site-packages/flask/app.py", line 1952, in full_dispatch_request
    rv = self.handle_user_exception(e)
  File "/home/guido/anaconda3/envs/local/lib/python3.8/site-packages/flask/app.py", line 1821, in handle_user_exception
    reraise(exc_type, exc_value, tb)
  File "/home/guido/anaconda3/envs/local/lib/python3.8/site-packages/flask/_compat.py", line 39, in reraise
    raise value
  File "/home/guido/anaconda3/envs/local/lib/python3.8/site-packages/flask/app.py", line 1950, in full_dispatch_request
    rv = self.dispatch_request()
  File "/home/guido/anaconda3/envs/local/lib/python3.8/site-packages/flask/app.py", line 1936, in dispatch_request
    return self.view_functions[rule.endpoint](**req.view_args)
  File "/home/guido/anaconda3/envs/local/lib/python3.8/site-packages/flask_login/utils.py", line 272, in decorated_view
    return func(*args, **kwargs)
  File "/home/guido/Dropbox/cs50x/final_project/app/routes.py", line 175, in bet
    return render_template("bet.html", title='Home Page', table=next_round, form=form)
  File "/home/guido/anaconda3/envs/local/lib/python3.8/site-packages/flask/templating.py", line 138, in render_template
    ctx.app.jinja_env.get_or_select_template(template_name_or_list),
  File "/home/guido/anaconda3/envs/local/lib/python3.8/site-packages/jinja2/environment.py", line 930, in get_or_select_template
    return self.get_template(template_name_or_list, parent, globals)
  File "/home/guido/anaconda3/envs/local/lib/python3.8/site-packages/jinja2/environment.py", line 883, in get_template
    return self._load_template(name, self.make_globals(globals))
  File "/home/guido/anaconda3/envs/local/lib/python3.8/site-packages/jinja2/environment.py", line 857, in _load_template
    template = self.loader.load(self, name, globals)
  File "/home/guido/anaconda3/envs/local/lib/python3.8/site-packages/jinja2/loaders.py", line 127, in load
    code = environment.compile(source, name, filename)
  File "/home/guido/anaconda3/envs/local/lib/python3.8/site-packages/jinja2/environment.py", line 638, in compile
    self.handle_exception(source=source_hint)
  File "/home/guido/anaconda3/envs/local/lib/python3.8/site-packages/jinja2/environment.py", line 832, in handle_exception
    reraise(*rewrite_traceback_stack(source=source))
  File "/home/guido/anaconda3/envs/local/lib/python3.8/site-packages/jinja2/_compat.py", line 28, in reraise
    raise value.with_traceback(tb)
  File "/home/guido/Dropbox/cs50x/final_project/app/templates/bet.html", line 7, in template
    {% get_flashed_messages() %}
jinja2.exceptions.TemplateSyntaxError: Encountered unknown tag 'get_flashed_messages'. Jinja was looking for the following tags: 'endblock'. The innermost block that needs to be closed is 'block'.
2020-09-24 15:56:25,856 INFO: Futbolero startup [in /home/guido/Dropbox/cs50x/final_project/app/__init__.py:37]
2020-09-24 15:56:44,151 ERROR: Exception on /bet [POST] [in /home/guido/anaconda3/envs/local/lib/python3.8/site-packages/flask/app.py:1891]
Traceback (most recent call last):
  File "/home/guido/anaconda3/envs/local/lib/python3.8/site-packages/flask/app.py", line 2447, in wsgi_app
    response = self.full_dispatch_request()
  File "/home/guido/anaconda3/envs/local/lib/python3.8/site-packages/flask/app.py", line 1952, in full_dispatch_request
    rv = self.handle_user_exception(e)
  File "/home/guido/anaconda3/envs/local/lib/python3.8/site-packages/flask/app.py", line 1821, in handle_user_exception
    reraise(exc_type, exc_value, tb)
  File "/home/guido/anaconda3/envs/local/lib/python3.8/site-packages/flask/_compat.py", line 39, in reraise
    raise value
  File "/home/guido/anaconda3/envs/local/lib/python3.8/site-packages/flask/app.py", line 1950, in full_dispatch_request
    rv = self.dispatch_request()
  File "/home/guido/anaconda3/envs/local/lib/python3.8/site-packages/flask/app.py", line 1936, in dispatch_request
    return self.view_functions[rule.endpoint](**req.view_args)
  File "/home/guido/anaconda3/envs/local/lib/python3.8/site-packages/flask_login/utils.py", line 272, in decorated_view
    return func(*args, **kwargs)
  File "/home/guido/Dropbox/cs50x/final_project/app/routes.py", line 171, in bet
    if form.validate_on_submit():
  File "/home/guido/anaconda3/envs/local/lib/python3.8/site-packages/flask_wtf/form.py", line 100, in validate_on_submit
    return self.is_submitted() and self.validate()
  File "/home/guido/anaconda3/envs/local/lib/python3.8/site-packages/wtforms/form.py", line 318, in validate
    return super(Form, self).validate(extra)
  File "/home/guido/anaconda3/envs/local/lib/python3.8/site-packages/wtforms/form.py", line 150, in validate
    if not field.validate(self, extra):
  File "/home/guido/anaconda3/envs/local/lib/python3.8/site-packages/wtforms/fields/core.py", line 996, in validate
    self._run_validation_chain(form, chain)
  File "/home/guido/anaconda3/envs/local/lib/python3.8/site-packages/wtforms/fields/core.py", line 246, in _run_validation_chain
    validator(form, self)
  File "/home/guido/Dropbox/cs50x/final_project/app/forms.py", line 71, in validate_bet
    print(field.data)
AttributeError: 'dict' object has no attribute 'data'
