2020-09-30 10:14:42,535 INFO: Futbolero startup [in /home/guido/Dropbox/cs50x/final_project/app/__init__.py:37]
2020-09-30 10:15:05,832 INFO: Futbolero startup [in /home/guido/Dropbox/cs50x/final_project/app/__init__.py:37]
2020-09-30 10:15:21,616 INFO: Futbolero startup [in /home/guido/Dropbox/cs50x/final_project/app/__init__.py:37]
2020-09-30 10:22:26,161 INFO: Futbolero startup [in /home/guido/Dropbox/cs50x/final_project/app/__init__.py:37]
2020-09-30 10:25:26,537 INFO: Futbolero startup [in /home/guido/Dropbox/cs50x/final_project/app/__init__.py:37]
2020-09-30 10:44:53,376 INFO: Futbolero startup [in /home/guido/Dropbox/cs50x/final_project/app/__init__.py:37]
2020-09-30 10:48:56,484 INFO: Futbolero startup [in /home/guido/Dropbox/cs50x/final_project/app/__init__.py:37]
2020-09-30 11:41:30,693 INFO: Futbolero startup [in /home/guido/Dropbox/cs50x/final_project/app/__init__.py:37]
2020-09-30 11:41:40,221 ERROR: Exception on /user/guido [GET] [in /home/guido/anaconda3/envs/local/lib/python3.8/site-packages/flask/app.py:1891]
Traceback (most recent call last):
  File "/home/guido/anaconda3/envs/local/lib/python3.8/site-packages/flask/app.py", line 2447, in wsgi_app
    response = self.full_dispatch_request()
  File "/home/guido/anaconda3/envs/local/lib/python3.8/site-packages/flask/app.py", line 1952, in full_dispatch_request
    rv = self.handle_user_exception(e)
  File "/home/guido/anaconda3/envs/local/lib/python3.8/site-packages/flask/app.py", line 1821, in handle_user_exception
    reraise(exc_type, exc_value, tb)
  File "/home/guido/anaconda3/envs/local/lib/python3.8/site-packages/flask/_compat.py", line 39, in reraise
    raise value
  File "/home/guido/anaconda3/envs/local/lib/python3.8/site-packages/flask/app.py", line 1950, in full_dispatch_request
    rv = self.dispatch_request()
  File "/home/guido/anaconda3/envs/local/lib/python3.8/site-packages/flask/app.py", line 1936, in dispatch_request
    return self.view_functions[rule.endpoint](**req.view_args)
  File "/home/guido/anaconda3/envs/local/lib/python3.8/site-packages/flask_login/utils.py", line 272, in decorated_view
    return func(*args, **kwargs)
  File "/home/guido/Dropbox/cs50x/final_project/app/routes.py", line 121, in user
    user_list = [{'nombre':user.username,'puntos': user.rank.first().points} for user in users]
  File "/home/guido/Dropbox/cs50x/final_project/app/routes.py", line 121, in <listcomp>
    user_list = [{'nombre':user.username,'puntos': user.rank.first().points} for user in users]
AttributeError: 'NoneType' object has no attribute 'points'
2020-09-30 11:41:47,455 ERROR: Exception on /user/guido [GET] [in /home/guido/anaconda3/envs/local/lib/python3.8/site-packages/flask/app.py:1891]
Traceback (most recent call last):
  File "/home/guido/anaconda3/envs/local/lib/python3.8/site-packages/flask/app.py", line 2447, in wsgi_app
    response = self.full_dispatch_request()
  File "/home/guido/anaconda3/envs/local/lib/python3.8/site-packages/flask/app.py", line 1952, in full_dispatch_request
    rv = self.handle_user_exception(e)
  File "/home/guido/anaconda3/envs/local/lib/python3.8/site-packages/flask/app.py", line 1821, in handle_user_exception
    reraise(exc_type, exc_value, tb)
  File "/home/guido/anaconda3/envs/local/lib/python3.8/site-packages/flask/_compat.py", line 39, in reraise
    raise value
  File "/home/guido/anaconda3/envs/local/lib/python3.8/site-packages/flask/app.py", line 1950, in full_dispatch_request
    rv = self.dispatch_request()
  File "/home/guido/anaconda3/envs/local/lib/python3.8/site-packages/flask/app.py", line 1936, in dispatch_request
    return self.view_functions[rule.endpoint](**req.view_args)
  File "/home/guido/anaconda3/envs/local/lib/python3.8/site-packages/flask_login/utils.py", line 272, in decorated_view
    return func(*args, **kwargs)
  File "/home/guido/Dropbox/cs50x/final_project/app/routes.py", line 121, in user
    user_list = [{'nombre':user.username,'puntos': user.rank.first().points} for user in users]
  File "/home/guido/Dropbox/cs50x/final_project/app/routes.py", line 121, in <listcomp>
    user_list = [{'nombre':user.username,'puntos': user.rank.first().points} for user in users]
AttributeError: 'NoneType' object has no attribute 'points'
2020-09-30 11:44:38,489 INFO: Futbolero startup [in /home/guido/Dropbox/cs50x/final_project/app/__init__.py:37]
2020-09-30 11:44:52,519 INFO: Futbolero startup [in /home/guido/Dropbox/cs50x/final_project/app/__init__.py:37]
2020-09-30 11:45:03,557 INFO: Futbolero startup [in /home/guido/Dropbox/cs50x/final_project/app/__init__.py:37]
2020-09-30 11:52:16,112 INFO: Futbolero startup [in /home/guido/Dropbox/cs50x/final_project/app/__init__.py:37]
2020-09-30 11:52:30,564 INFO: Futbolero startup [in /home/guido/Dropbox/cs50x/final_project/app/__init__.py:37]
2020-09-30 11:52:48,816 INFO: Futbolero startup [in /home/guido/Dropbox/cs50x/final_project/app/__init__.py:37]
2020-09-30 11:53:08,123 INFO: Futbolero startup [in /home/guido/Dropbox/cs50x/final_project/app/__init__.py:37]
2020-09-30 11:53:34,104 INFO: Futbolero startup [in /home/guido/Dropbox/cs50x/final_project/app/__init__.py:37]
2020-09-30 11:54:21,522 INFO: Futbolero startup [in /home/guido/Dropbox/cs50x/final_project/app/__init__.py:37]
2020-09-30 11:54:57,492 INFO: Futbolero startup [in /home/guido/Dropbox/cs50x/final_project/app/__init__.py:37]
2020-09-30 14:46:40,019 INFO: Futbolero startup [in /home/guido/Dropbox/cs50x/final_project/app/__init__.py:37]
2020-09-30 14:46:51,302 INFO: Futbolero startup [in /home/guido/Dropbox/cs50x/final_project/app/__init__.py:37]
2020-09-30 14:47:25,251 INFO: Futbolero startup [in /home/guido/Dropbox/cs50x/final_project/app/__init__.py:37]
2020-09-30 14:47:44,665 INFO: Futbolero startup [in /home/guido/Dropbox/cs50x/final_project/app/__init__.py:37]
2020-09-30 14:56:48,977 INFO: Futbolero startup [in /home/guido/Dropbox/cs50x/final_project/app/__init__.py:37]
2020-09-30 14:59:53,120 INFO: Futbolero startup [in /home/guido/Dropbox/cs50x/final_project/app/__init__.py:37]
2020-09-30 15:00:01,189 INFO: Futbolero startup [in /home/guido/Dropbox/cs50x/final_project/app/__init__.py:37]
2020-09-30 15:01:23,333 INFO: Futbolero startup [in /home/guido/Dropbox/cs50x/final_project/app/__init__.py:37]
2020-09-30 15:03:53,056 INFO: Futbolero startup [in /home/guido/Dropbox/cs50x/final_project/app/__init__.py:37]
2020-09-30 15:15:53,798 INFO: Futbolero startup [in /home/guido/Dropbox/cs50x/final_project/app/__init__.py:37]
2020-09-30 15:16:57,796 INFO: Futbolero startup [in /home/guido/Dropbox/cs50x/final_project/app/__init__.py:37]
2020-09-30 15:17:06,814 INFO: Futbolero startup [in /home/guido/Dropbox/cs50x/final_project/app/__init__.py:37]
2020-09-30 15:17:21,465 INFO: Futbolero startup [in /home/guido/Dropbox/cs50x/final_project/app/__init__.py:37]
2020-09-30 15:17:33,369 INFO: Futbolero startup [in /home/guido/Dropbox/cs50x/final_project/app/__init__.py:37]
2020-09-30 15:17:49,484 INFO: Futbolero startup [in /home/guido/Dropbox/cs50x/final_project/app/__init__.py:37]
2020-09-30 15:18:13,129 INFO: Futbolero startup [in /home/guido/Dropbox/cs50x/final_project/app/__init__.py:37]
2020-09-30 15:19:15,834 INFO: Futbolero startup [in /home/guido/Dropbox/cs50x/final_project/app/__init__.py:37]
2020-09-30 15:21:57,280 INFO: Futbolero startup [in /home/guido/Dropbox/cs50x/final_project/app/__init__.py:37]
2020-09-30 15:22:05,399 INFO: Futbolero startup [in /home/guido/Dropbox/cs50x/final_project/app/__init__.py:37]
2020-09-30 15:22:24,120 INFO: Futbolero startup [in /home/guido/Dropbox/cs50x/final_project/app/__init__.py:37]
2020-09-30 15:25:31,245 INFO: Futbolero startup [in /home/guido/Dropbox/cs50x/final_project/app/__init__.py:37]
2020-09-30 15:28:04,702 INFO: Futbolero startup [in /home/guido/Dropbox/cs50x/final_project/app/__init__.py:37]
2020-09-30 15:28:08,356 ERROR: Exception on / [GET] [in /home/guido/anaconda3/envs/local/lib/python3.8/site-packages/flask/app.py:1891]
Traceback (most recent call last):
  File "/home/guido/anaconda3/envs/local/lib/python3.8/site-packages/flask/app.py", line 2447, in wsgi_app
    response = self.full_dispatch_request()
  File "/home/guido/anaconda3/envs/local/lib/python3.8/site-packages/flask/app.py", line 1952, in full_dispatch_request
    rv = self.handle_user_exception(e)
  File "/home/guido/anaconda3/envs/local/lib/python3.8/site-packages/flask/app.py", line 1821, in handle_user_exception
    reraise(exc_type, exc_value, tb)
  File "/home/guido/anaconda3/envs/local/lib/python3.8/site-packages/flask/_compat.py", line 39, in reraise
    raise value
  File "/home/guido/anaconda3/envs/local/lib/python3.8/site-packages/flask/app.py", line 1950, in full_dispatch_request
    rv = self.dispatch_request()
  File "/home/guido/anaconda3/envs/local/lib/python3.8/site-packages/flask/app.py", line 1936, in dispatch_request
    return self.view_functions[rule.endpoint](**req.view_args)
  File "/home/guido/anaconda3/envs/local/lib/python3.8/site-packages/flask_login/utils.py", line 272, in decorated_view
    return func(*args, **kwargs)
  File "/home/guido/Dropbox/cs50x/final_project/app/routes.py", line 40, in index
    rounds = [matches['round'] for matches in fixture if datetime.strptime(matches['date'], '%d-%m-%Y').date() <= datetime.utcnow().date()]
NameError: name 'fixture' is not defined
2020-09-30 15:28:29,520 INFO: Futbolero startup [in /home/guido/Dropbox/cs50x/final_project/app/__init__.py:37]
