2020-10-09 13:08:23,478 ERROR: Exception on /user/mauri [GET] [in /home/guido/anaconda3/envs/local/lib/python3.8/site-packages/flask/app.py:1891]
Traceback (most recent call last):
  File "/home/guido/anaconda3/envs/local/lib/python3.8/site-packages/flask/app.py", line 2447, in wsgi_app
    response = self.full_dispatch_request()
  File "/home/guido/anaconda3/envs/local/lib/python3.8/site-packages/flask/app.py", line 1952, in full_dispatch_request
    rv = self.handle_user_exception(e)
  File "/home/guido/anaconda3/envs/local/lib/python3.8/site-packages/flask/app.py", line 1821, in handle_user_exception
    reraise(exc_type, exc_value, tb)
  File "/home/guido/anaconda3/envs/local/lib/python3.8/site-packages/flask/_compat.py", line 39, in reraise
    raise value
  File "/home/guido/anaconda3/envs/local/lib/python3.8/site-packages/flask/app.py", line 1950, in full_dispatch_request
    rv = self.dispatch_request()
  File "/home/guido/anaconda3/envs/local/lib/python3.8/site-packages/flask/app.py", line 1936, in dispatch_request
    return self.view_functions[rule.endpoint](**req.view_args)
  File "/home/guido/anaconda3/envs/local/lib/python3.8/site-packages/flask_login/utils.py", line 272, in decorated_view
    return func(*args, **kwargs)
  File "/home/guido/Dropbox/cs50x/final_project/app/routes.py", line 111, in user
    helpers.points_plot(fixture)
  File "/home/guido/Dropbox/cs50x/final_project/app/helpers.py", line 161, in points_plot
    users = [user.username for user in q]
NameError: name 'q' is not defined
2020-10-09 13:08:39,604 INFO: Futbolero startup [in /home/guido/Dropbox/cs50x/final_project/app/__init__.py:42]
2020-10-09 14:27:34,804 INFO: Futbolero startup [in /home/guido/Dropbox/cs50x/final_project/app/__init__.py:42]
2020-10-09 14:27:53,885 ERROR: Exception on /user/paula [GET] [in /home/guido/anaconda3/envs/local/lib/python3.8/site-packages/flask/app.py:1891]
Traceback (most recent call last):
  File "/home/guido/anaconda3/envs/local/lib/python3.8/site-packages/flask/app.py", line 2447, in wsgi_app
    response = self.full_dispatch_request()
  File "/home/guido/anaconda3/envs/local/lib/python3.8/site-packages/flask/app.py", line 1952, in full_dispatch_request
    rv = self.handle_user_exception(e)
  File "/home/guido/anaconda3/envs/local/lib/python3.8/site-packages/flask/app.py", line 1821, in handle_user_exception
    reraise(exc_type, exc_value, tb)
  File "/home/guido/anaconda3/envs/local/lib/python3.8/site-packages/flask/_compat.py", line 39, in reraise
    raise value
  File "/home/guido/anaconda3/envs/local/lib/python3.8/site-packages/flask/app.py", line 1950, in full_dispatch_request
    rv = self.dispatch_request()
  File "/home/guido/anaconda3/envs/local/lib/python3.8/site-packages/flask/app.py", line 1936, in dispatch_request
    return self.view_functions[rule.endpoint](**req.view_args)
  File "/home/guido/anaconda3/envs/local/lib/python3.8/site-packages/flask_login/utils.py", line 272, in decorated_view
    return func(*args, **kwargs)
  File "/home/guido/Dropbox/cs50x/final_project/app/routes.py", line 111, in user
    helpers.points_plot(fixture)
  File "/home/guido/Dropbox/cs50x/final_project/app/helpers.py", line 182, in points_plot
    fig.write_html("/templates/chart.html")
  File "/home/guido/anaconda3/envs/local/lib/python3.8/site-packages/plotly/basedatatypes.py", line 3159, in write_html
    return pio.write_html(self, *args, **kwargs)
  File "/home/guido/anaconda3/envs/local/lib/python3.8/site-packages/plotly/io/_html.py", line 527, in write_html
    with open(file, "w") as f:
FileNotFoundError: [Errno 2] No such file or directory: '/templates/chart.html'
2020-10-09 14:28:20,954 INFO: Futbolero startup [in /home/guido/Dropbox/cs50x/final_project/app/__init__.py:42]
2020-10-09 14:29:23,122 INFO: Futbolero startup [in /home/guido/Dropbox/cs50x/final_project/app/__init__.py:42]
2020-10-09 14:29:36,765 ERROR: Exception on /user/paula [GET] [in /home/guido/anaconda3/envs/local/lib/python3.8/site-packages/flask/app.py:1891]
Traceback (most recent call last):
  File "/home/guido/anaconda3/envs/local/lib/python3.8/site-packages/flask/app.py", line 2447, in wsgi_app
    response = self.full_dispatch_request()
  File "/home/guido/anaconda3/envs/local/lib/python3.8/site-packages/flask/app.py", line 1952, in full_dispatch_request
    rv = self.handle_user_exception(e)
  File "/home/guido/anaconda3/envs/local/lib/python3.8/site-packages/flask/app.py", line 1821, in handle_user_exception
    reraise(exc_type, exc_value, tb)
  File "/home/guido/anaconda3/envs/local/lib/python3.8/site-packages/flask/_compat.py", line 39, in reraise
    raise value
  File "/home/guido/anaconda3/envs/local/lib/python3.8/site-packages/flask/app.py", line 1950, in full_dispatch_request
    rv = self.dispatch_request()
  File "/home/guido/anaconda3/envs/local/lib/python3.8/site-packages/flask/app.py", line 1936, in dispatch_request
    return self.view_functions[rule.endpoint](**req.view_args)
  File "/home/guido/anaconda3/envs/local/lib/python3.8/site-packages/flask_login/utils.py", line 272, in decorated_view
    return func(*args, **kwargs)
  File "/home/guido/Dropbox/cs50x/final_project/app/routes.py", line 111, in user
    helpers.points_plot(fixture)
  File "/home/guido/Dropbox/cs50x/final_project/app/helpers.py", line 182, in points_plot
    fig.write_html("/app/static/chart.html")
  File "/home/guido/anaconda3/envs/local/lib/python3.8/site-packages/plotly/basedatatypes.py", line 3159, in write_html
    return pio.write_html(self, *args, **kwargs)
  File "/home/guido/anaconda3/envs/local/lib/python3.8/site-packages/plotly/io/_html.py", line 527, in write_html
    with open(file, "w") as f:
FileNotFoundError: [Errno 2] No such file or directory: '/app/static/chart.html'
2020-10-09 14:30:24,568 INFO: Futbolero startup [in /home/guido/Dropbox/cs50x/final_project/app/__init__.py:42]
2020-10-09 14:30:35,492 ERROR: Exception on /user/paula [GET] [in /home/guido/anaconda3/envs/local/lib/python3.8/site-packages/flask/app.py:1891]
Traceback (most recent call last):
  File "/home/guido/anaconda3/envs/local/lib/python3.8/site-packages/flask/app.py", line 2447, in wsgi_app
    response = self.full_dispatch_request()
  File "/home/guido/anaconda3/envs/local/lib/python3.8/site-packages/flask/app.py", line 1952, in full_dispatch_request
    rv = self.handle_user_exception(e)
  File "/home/guido/anaconda3/envs/local/lib/python3.8/site-packages/flask/app.py", line 1821, in handle_user_exception
    reraise(exc_type, exc_value, tb)
  File "/home/guido/anaconda3/envs/local/lib/python3.8/site-packages/flask/_compat.py", line 39, in reraise
    raise value
  File "/home/guido/anaconda3/envs/local/lib/python3.8/site-packages/flask/app.py", line 1950, in full_dispatch_request
    rv = self.dispatch_request()
  File "/home/guido/anaconda3/envs/local/lib/python3.8/site-packages/flask/app.py", line 1936, in dispatch_request
    return self.view_functions[rule.endpoint](**req.view_args)
  File "/home/guido/anaconda3/envs/local/lib/python3.8/site-packages/flask_login/utils.py", line 272, in decorated_view
    return func(*args, **kwargs)
  File "/home/guido/Dropbox/cs50x/final_project/app/routes.py", line 111, in user
    helpers.points_plot(fixture)
  File "/home/guido/Dropbox/cs50x/final_project/app/helpers.py", line 182, in points_plot
    fig.write_html("/static/chart.html")
  File "/home/guido/anaconda3/envs/local/lib/python3.8/site-packages/plotly/basedatatypes.py", line 3159, in write_html
    return pio.write_html(self, *args, **kwargs)
  File "/home/guido/anaconda3/envs/local/lib/python3.8/site-packages/plotly/io/_html.py", line 527, in write_html
    with open(file, "w") as f:
FileNotFoundError: [Errno 2] No such file or directory: '/static/chart.html'
2020-10-09 14:31:00,448 INFO: Futbolero startup [in /home/guido/Dropbox/cs50x/final_project/app/__init__.py:42]
2020-10-09 14:31:12,883 ERROR: Exception on /user/paula [GET] [in /home/guido/anaconda3/envs/local/lib/python3.8/site-packages/flask/app.py:1891]
Traceback (most recent call last):
  File "/home/guido/anaconda3/envs/local/lib/python3.8/site-packages/flask/app.py", line 2447, in wsgi_app
    response = self.full_dispatch_request()
  File "/home/guido/anaconda3/envs/local/lib/python3.8/site-packages/flask/app.py", line 1952, in full_dispatch_request
    rv = self.handle_user_exception(e)
  File "/home/guido/anaconda3/envs/local/lib/python3.8/site-packages/flask/app.py", line 1821, in handle_user_exception
    reraise(exc_type, exc_value, tb)
  File "/home/guido/anaconda3/envs/local/lib/python3.8/site-packages/flask/_compat.py", line 39, in reraise
    raise value
  File "/home/guido/anaconda3/envs/local/lib/python3.8/site-packages/flask/app.py", line 1950, in full_dispatch_request
    rv = self.dispatch_request()
  File "/home/guido/anaconda3/envs/local/lib/python3.8/site-packages/flask/app.py", line 1936, in dispatch_request
    return self.view_functions[rule.endpoint](**req.view_args)
  File "/home/guido/anaconda3/envs/local/lib/python3.8/site-packages/flask_login/utils.py", line 272, in decorated_view
    return func(*args, **kwargs)
  File "/home/guido/Dropbox/cs50x/final_project/app/routes.py", line 111, in user
    helpers.points_plot(fixture)
  File "/home/guido/Dropbox/cs50x/final_project/app/helpers.py", line 182, in points_plot
    fig.write_html("static/chart.html")
  File "/home/guido/anaconda3/envs/local/lib/python3.8/site-packages/plotly/basedatatypes.py", line 3159, in write_html
    return pio.write_html(self, *args, **kwargs)
  File "/home/guido/anaconda3/envs/local/lib/python3.8/site-packages/plotly/io/_html.py", line 527, in write_html
    with open(file, "w") as f:
FileNotFoundError: [Errno 2] No such file or directory: 'static/chart.html'
2020-10-09 14:31:43,714 INFO: Futbolero startup [in /home/guido/Dropbox/cs50x/final_project/app/__init__.py:42]
