2020-09-30 15:28:47,179 ERROR: Exception on /user/guido [GET] [in /home/guido/anaconda3/envs/local/lib/python3.8/site-packages/flask/app.py:1891]
Traceback (most recent call last):
  File "/home/guido/anaconda3/envs/local/lib/python3.8/site-packages/flask/app.py", line 2447, in wsgi_app
    response = self.full_dispatch_request()
  File "/home/guido/anaconda3/envs/local/lib/python3.8/site-packages/flask/app.py", line 1952, in full_dispatch_request
    rv = self.handle_user_exception(e)
  File "/home/guido/anaconda3/envs/local/lib/python3.8/site-packages/flask/app.py", line 1821, in handle_user_exception
    reraise(exc_type, exc_value, tb)
  File "/home/guido/anaconda3/envs/local/lib/python3.8/site-packages/flask/_compat.py", line 39, in reraise
    raise value
  File "/home/guido/anaconda3/envs/local/lib/python3.8/site-packages/flask/app.py", line 1950, in full_dispatch_request
    rv = self.dispatch_request()
  File "/home/guido/anaconda3/envs/local/lib/python3.8/site-packages/flask/app.py", line 1936, in dispatch_request
    return self.view_functions[rule.endpoint](**req.view_args)
  File "/home/guido/anaconda3/envs/local/lib/python3.8/site-packages/flask_login/utils.py", line 272, in decorated_view
    return func(*args, **kwargs)
  File "/home/guido/Dropbox/cs50x/final_project/app/routes.py", line 122, in user
    users_points = db.session.query(Points.user_id, db.func.max(Points.score_away)).group_by(Points.user_id).all()
AttributeError: type object 'Points' has no attribute 'score_away'
2020-09-30 15:31:40,492 INFO: Futbolero startup [in /home/guido/Dropbox/cs50x/final_project/app/__init__.py:37]
2020-09-30 15:31:54,049 ERROR: Exception on /user/guido [GET] [in /home/guido/anaconda3/envs/local/lib/python3.8/site-packages/flask/app.py:1891]
Traceback (most recent call last):
  File "/home/guido/anaconda3/envs/local/lib/python3.8/site-packages/flask/app.py", line 2447, in wsgi_app
    response = self.full_dispatch_request()
  File "/home/guido/anaconda3/envs/local/lib/python3.8/site-packages/flask/app.py", line 1952, in full_dispatch_request
    rv = self.handle_user_exception(e)
  File "/home/guido/anaconda3/envs/local/lib/python3.8/site-packages/flask/app.py", line 1821, in handle_user_exception
    reraise(exc_type, exc_value, tb)
  File "/home/guido/anaconda3/envs/local/lib/python3.8/site-packages/flask/_compat.py", line 39, in reraise
    raise value
  File "/home/guido/anaconda3/envs/local/lib/python3.8/site-packages/flask/app.py", line 1950, in full_dispatch_request
    rv = self.dispatch_request()
  File "/home/guido/anaconda3/envs/local/lib/python3.8/site-packages/flask/app.py", line 1936, in dispatch_request
    return self.view_functions[rule.endpoint](**req.view_args)
  File "/home/guido/anaconda3/envs/local/lib/python3.8/site-packages/flask_login/utils.py", line 272, in decorated_view
    return func(*args, **kwargs)
  File "/home/guido/Dropbox/cs50x/final_project/app/routes.py", line 126, in user
    if users[row].id == users_points[row][0]:
IndexError: list index out of range
2020-09-30 15:32:51,914 INFO: Futbolero startup [in /home/guido/Dropbox/cs50x/final_project/app/__init__.py:37]
2020-09-30 15:38:34,869 INFO: Futbolero startup [in /home/guido/Dropbox/cs50x/final_project/app/__init__.py:37]
2020-09-30 15:38:46,911 ERROR: Exception on /user/guido [GET] [in /home/guido/anaconda3/envs/local/lib/python3.8/site-packages/flask/app.py:1891]
Traceback (most recent call last):
  File "/home/guido/anaconda3/envs/local/lib/python3.8/site-packages/flask/app.py", line 2447, in wsgi_app
    response = self.full_dispatch_request()
  File "/home/guido/anaconda3/envs/local/lib/python3.8/site-packages/flask/app.py", line 1952, in full_dispatch_request
    rv = self.handle_user_exception(e)
  File "/home/guido/anaconda3/envs/local/lib/python3.8/site-packages/flask/app.py", line 1821, in handle_user_exception
    reraise(exc_type, exc_value, tb)
  File "/home/guido/anaconda3/envs/local/lib/python3.8/site-packages/flask/_compat.py", line 39, in reraise
    raise value
  File "/home/guido/anaconda3/envs/local/lib/python3.8/site-packages/flask/app.py", line 1950, in full_dispatch_request
    rv = self.dispatch_request()
  File "/home/guido/anaconda3/envs/local/lib/python3.8/site-packages/flask/app.py", line 1936, in dispatch_request
    return self.view_functions[rule.endpoint](**req.view_args)
  File "/home/guido/anaconda3/envs/local/lib/python3.8/site-packages/flask_login/utils.py", line 272, in decorated_view
    return func(*args, **kwargs)
  File "/home/guido/Dropbox/cs50x/final_project/app/routes.py", line 138, in user
    ranking=enumerate(ranking))
TypeError: 'bool' object is not iterable
2020-09-30 15:39:03,468 INFO: Futbolero startup [in /home/guido/Dropbox/cs50x/final_project/app/__init__.py:37]
