2020-09-24 10:41:13,502 ERROR: Exception on /bet [GET] [in /home/guido/anaconda3/envs/local/lib/python3.8/site-packages/flask/app.py:1891]
Traceback (most recent call last):
  File "/home/guido/anaconda3/envs/local/lib/python3.8/site-packages/flask/app.py", line 2447, in wsgi_app
    response = self.full_dispatch_request()
  File "/home/guido/anaconda3/envs/local/lib/python3.8/site-packages/flask/app.py", line 1952, in full_dispatch_request
    rv = self.handle_user_exception(e)
  File "/home/guido/anaconda3/envs/local/lib/python3.8/site-packages/flask/app.py", line 1821, in handle_user_exception
    reraise(exc_type, exc_value, tb)
  File "/home/guido/anaconda3/envs/local/lib/python3.8/site-packages/flask/_compat.py", line 39, in reraise
    raise value
  File "/home/guido/anaconda3/envs/local/lib/python3.8/site-packages/flask/app.py", line 1950, in full_dispatch_request
    rv = self.dispatch_request()
  File "/home/guido/anaconda3/envs/local/lib/python3.8/site-packages/flask/app.py", line 1936, in dispatch_request
    return self.view_functions[rule.endpoint](**req.view_args)
  File "/home/guido/anaconda3/envs/local/lib/python3.8/site-packages/flask_login/utils.py", line 272, in decorated_view
    return func(*args, **kwargs)
  File "/home/guido/Dropbox/cs50x/final_project/app/routes.py", line 175, in bet
    return render_template("bet.html", title='Home Page', table=next_round, form=form)
  File "/home/guido/anaconda3/envs/local/lib/python3.8/site-packages/flask/templating.py", line 137, in render_template
    return _render(
  File "/home/guido/anaconda3/envs/local/lib/python3.8/site-packages/flask/templating.py", line 120, in _render
    rv = template.render(context)
  File "/home/guido/anaconda3/envs/local/lib/python3.8/site-packages/jinja2/environment.py", line 1090, in render
    self.environment.handle_exception()
  File "/home/guido/anaconda3/envs/local/lib/python3.8/site-packages/jinja2/environment.py", line 832, in handle_exception
    reraise(*rewrite_traceback_stack(source=source))
  File "/home/guido/anaconda3/envs/local/lib/python3.8/site-packages/jinja2/_compat.py", line 28, in reraise
    raise value.with_traceback(tb)
  File "/home/guido/Dropbox/cs50x/final_project/app/templates/bet.html", line 2, in top-level template code
    {% extends "base.html" %}
  File "/home/guido/Dropbox/cs50x/final_project/app/templates/base.html", line 43, in top-level template code
    {% block content %}{% endblock %}
  File "/home/guido/Dropbox/cs50x/final_project/app/templates/bet.html", line 34, in block "content"
    <td>{{ form.bet[row].home }}</td>
  File "/home/guido/anaconda3/envs/local/lib/python3.8/site-packages/jinja2/environment.py", line 452, in getitem
    return obj[argument]
jinja2.exceptions.UndefinedError: 'list object' has no attribute 'bet'
2020-09-24 10:45:22,005 INFO: Futbolero startup [in /home/guido/Dropbox/cs50x/final_project/app/__init__.py:37]
2020-09-24 10:46:00,728 INFO: Futbolero startup [in /home/guido/Dropbox/cs50x/final_project/app/__init__.py:37]
2020-09-24 10:51:08,150 INFO: Futbolero startup [in /home/guido/Dropbox/cs50x/final_project/app/__init__.py:37]
2020-09-24 10:58:08,625 INFO: Futbolero startup [in /home/guido/Dropbox/cs50x/final_project/app/__init__.py:37]
2020-09-24 11:10:32,912 INFO: Futbolero startup [in /home/guido/Dropbox/cs50x/final_project/app/__init__.py:37]
2020-09-24 11:10:55,146 ERROR: Exception on /bet [POST] [in /home/guido/anaconda3/envs/local/lib/python3.8/site-packages/flask/app.py:1891]
Traceback (most recent call last):
  File "/home/guido/anaconda3/envs/local/lib/python3.8/site-packages/flask/app.py", line 2447, in wsgi_app
    response = self.full_dispatch_request()
  File "/home/guido/anaconda3/envs/local/lib/python3.8/site-packages/flask/app.py", line 1952, in full_dispatch_request
    rv = self.handle_user_exception(e)
  File "/home/guido/anaconda3/envs/local/lib/python3.8/site-packages/flask/app.py", line 1821, in handle_user_exception
    reraise(exc_type, exc_value, tb)
  File "/home/guido/anaconda3/envs/local/lib/python3.8/site-packages/flask/_compat.py", line 39, in reraise
    raise value
  File "/home/guido/anaconda3/envs/local/lib/python3.8/site-packages/flask/app.py", line 1950, in full_dispatch_request
    rv = self.dispatch_request()
  File "/home/guido/anaconda3/envs/local/lib/python3.8/site-packages/flask/app.py", line 1936, in dispatch_request
    return self.view_functions[rule.endpoint](**req.view_args)
  File "/home/guido/anaconda3/envs/local/lib/python3.8/site-packages/flask_login/utils.py", line 272, in decorated_view
    return func(*args, **kwargs)
  File "/home/guido/Dropbox/cs50x/final_project/app/routes.py", line 172, in bet
    if form.validate_on_submit():
  File "/home/guido/anaconda3/envs/local/lib/python3.8/site-packages/flask_wtf/form.py", line 100, in validate_on_submit
    return self.is_submitted() and self.validate()
  File "/home/guido/anaconda3/envs/local/lib/python3.8/site-packages/wtforms/form.py", line 318, in validate
    return super(Form, self).validate(extra)
  File "/home/guido/anaconda3/envs/local/lib/python3.8/site-packages/wtforms/form.py", line 150, in validate
    if not field.validate(self, extra):
  File "/home/guido/anaconda3/envs/local/lib/python3.8/site-packages/wtforms/fields/core.py", line 989, in validate
    subfield.validate(form)
  File "/home/guido/anaconda3/envs/local/lib/python3.8/site-packages/wtforms/fields/core.py", line 871, in validate
    return self.form.validate()
  File "/home/guido/anaconda3/envs/local/lib/python3.8/site-packages/wtforms/form.py", line 318, in validate
    return super(Form, self).validate(extra)
  File "/home/guido/anaconda3/envs/local/lib/python3.8/site-packages/wtforms/form.py", line 150, in validate
    if not field.validate(self, extra):
  File "/home/guido/anaconda3/envs/local/lib/python3.8/site-packages/wtforms/fields/core.py", line 226, in validate
    stop_validation = self._run_validation_chain(form, chain)
  File "/home/guido/anaconda3/envs/local/lib/python3.8/site-packages/wtforms/fields/core.py", line 246, in _run_validation_chain
    validator(form, self)
  File "/home/guido/Dropbox/cs50x/final_project/app/forms.py", line 66, in validate_home
    if field.data is not int:
NameError: name 'field' is not defined
2020-09-24 11:11:23,726 INFO: Futbolero startup [in /home/guido/Dropbox/cs50x/final_project/app/__init__.py:37]
2020-09-24 11:14:31,653 INFO: Futbolero startup [in /home/guido/Dropbox/cs50x/final_project/app/__init__.py:37]
2020-09-24 11:18:08,376 INFO: Futbolero startup [in /home/guido/Dropbox/cs50x/final_project/app/__init__.py:37]
2020-09-24 11:18:30,271 ERROR: Exception on /bet [POST] [in /home/guido/anaconda3/envs/local/lib/python3.8/site-packages/flask/app.py:1891]
Traceback (most recent call last):
  File "/home/guido/anaconda3/envs/local/lib/python3.8/site-packages/flask/app.py", line 2447, in wsgi_app
    response = self.full_dispatch_request()
  File "/home/guido/anaconda3/envs/local/lib/python3.8/site-packages/flask/app.py", line 1952, in full_dispatch_request
    rv = self.handle_user_exception(e)
  File "/home/guido/anaconda3/envs/local/lib/python3.8/site-packages/flask/app.py", line 1821, in handle_user_exception
    reraise(exc_type, exc_value, tb)
  File "/home/guido/anaconda3/envs/local/lib/python3.8/site-packages/flask/_compat.py", line 39, in reraise
    raise value
  File "/home/guido/anaconda3/envs/local/lib/python3.8/site-packages/flask/app.py", line 1950, in full_dispatch_request
    rv = self.dispatch_request()
  File "/home/guido/anaconda3/envs/local/lib/python3.8/site-packages/flask/app.py", line 1936, in dispatch_request
    return self.view_functions[rule.endpoint](**req.view_args)
  File "/home/guido/anaconda3/envs/local/lib/python3.8/site-packages/flask_login/utils.py", line 272, in decorated_view
    return func(*args, **kwargs)
  File "/home/guido/Dropbox/cs50x/final_project/app/routes.py", line 172, in bet
    if form.validate_on_submit():
  File "/home/guido/anaconda3/envs/local/lib/python3.8/site-packages/flask_wtf/form.py", line 100, in validate_on_submit
    return self.is_submitted() and self.validate()
  File "/home/guido/anaconda3/envs/local/lib/python3.8/site-packages/wtforms/form.py", line 318, in validate
    return super(Form, self).validate(extra)
  File "/home/guido/anaconda3/envs/local/lib/python3.8/site-packages/wtforms/form.py", line 150, in validate
    if not field.validate(self, extra):
  File "/home/guido/anaconda3/envs/local/lib/python3.8/site-packages/wtforms/fields/core.py", line 989, in validate
    subfield.validate(form)
  File "/home/guido/anaconda3/envs/local/lib/python3.8/site-packages/wtforms/fields/core.py", line 871, in validate
    return self.form.validate()
  File "/home/guido/anaconda3/envs/local/lib/python3.8/site-packages/wtforms/form.py", line 318, in validate
    return super(Form, self).validate(extra)
  File "/home/guido/anaconda3/envs/local/lib/python3.8/site-packages/wtforms/form.py", line 150, in validate
    if not field.validate(self, extra):
  File "/home/guido/anaconda3/envs/local/lib/python3.8/site-packages/wtforms/fields/core.py", line 226, in validate
    stop_validation = self._run_validation_chain(form, chain)
  File "/home/guido/anaconda3/envs/local/lib/python3.8/site-packages/wtforms/fields/core.py", line 246, in _run_validation_chain
    validator(form, self)
  File "/home/guido/Dropbox/cs50x/final_project/app/forms.py", line 71, in validate_away
    print(home)
NameError: name 'home' is not defined
2020-09-24 11:19:15,803 INFO: Futbolero startup [in /home/guido/Dropbox/cs50x/final_project/app/__init__.py:37]
2020-09-24 11:32:24,291 INFO: Futbolero startup [in /home/guido/Dropbox/cs50x/final_project/app/__init__.py:37]
2020-09-24 14:02:19,619 INFO: Futbolero startup [in /home/guido/Dropbox/cs50x/final_project/app/__init__.py:37]
2020-09-24 15:08:04,159 INFO: Futbolero startup [in /home/guido/Dropbox/cs50x/final_project/app/__init__.py:37]
2020-09-24 15:13:24,182 INFO: Futbolero startup [in /home/guido/Dropbox/cs50x/final_project/app/__init__.py:37]
