2020-09-29 18:07:01,529 ERROR: Exception on /results [GET] [in /home/guido/anaconda3/envs/local/lib/python3.8/site-packages/flask/app.py:1891]
Traceback (most recent call last):
  File "/home/guido/anaconda3/envs/local/lib/python3.8/site-packages/flask/app.py", line 2447, in wsgi_app
    response = self.full_dispatch_request()
  File "/home/guido/anaconda3/envs/local/lib/python3.8/site-packages/flask/app.py", line 1952, in full_dispatch_request
    rv = self.handle_user_exception(e)
  File "/home/guido/anaconda3/envs/local/lib/python3.8/site-packages/flask/app.py", line 1821, in handle_user_exception
    reraise(exc_type, exc_value, tb)
  File "/home/guido/anaconda3/envs/local/lib/python3.8/site-packages/flask/_compat.py", line 39, in reraise
    raise value
  File "/home/guido/anaconda3/envs/local/lib/python3.8/site-packages/flask/app.py", line 1950, in full_dispatch_request
    rv = self.dispatch_request()
  File "/home/guido/anaconda3/envs/local/lib/python3.8/site-packages/flask/app.py", line 1936, in dispatch_request
    return self.view_functions[rule.endpoint](**req.view_args)
  File "/home/guido/anaconda3/envs/local/lib/python3.8/site-packages/flask_login/utils.py", line 272, in decorated_view
    return func(*args, **kwargs)
  File "/home/guido/Dropbox/cs50x/final_project/app/routes.py", line 291, in results
    if points_recorded[0] == None:
IndexError: list index out of range
2020-09-29 18:07:42,495 INFO: Futbolero startup [in /home/guido/Dropbox/cs50x/final_project/app/__init__.py:37]
